Failure # 1 (occurred at 2022-02-10_16-32-21)
Traceback (most recent call last):
  File "/Users/bumjin/opt/anaconda3/lib/python3.9/site-packages/ray/tune/trial_runner.py", line 893, in _process_trial
    results = self.trial_executor.fetch_result(trial)
  File "/Users/bumjin/opt/anaconda3/lib/python3.9/site-packages/ray/tune/ray_trial_executor.py", line 707, in fetch_result
    result = ray.get(trial_future[0], timeout=DEFAULT_GET_TIMEOUT)
  File "/Users/bumjin/opt/anaconda3/lib/python3.9/site-packages/ray/_private/client_mode_hook.py", line 105, in wrapper
    return func(*args, **kwargs)
  File "/Users/bumjin/opt/anaconda3/lib/python3.9/site-packages/ray/worker.py", line 1735, in get
    raise value
ray.exceptions.RayActorError: The actor died because of an error raised in its creation task, [36mray::DQNTrainer.__init__()[39m (pid=9099, ip=127.0.0.1)
  File "/Users/bumjin/opt/anaconda3/lib/python3.9/site-packages/ray/rllib/agents/trainer.py", line 923, in _init
    raise NotImplementedError
NotImplementedError

During handling of the above exception, another exception occurred:

[36mray::DQNTrainer.__init__()[39m (pid=9099, ip=127.0.0.1)
  File "/Users/bumjin/opt/anaconda3/lib/python3.9/site-packages/ray/rllib/agents/trainer.py", line 728, in __init__
    super().__init__(config, logger_creator, remote_checkpoint_dir,
  File "/Users/bumjin/opt/anaconda3/lib/python3.9/site-packages/ray/tune/trainable.py", line 122, in __init__
    self.setup(copy.deepcopy(self.config))
  File "/Users/bumjin/opt/anaconda3/lib/python3.9/site-packages/ray/rllib/agents/trainer.py", line 826, in setup
    self.workers = self._make_workers(
  File "/Users/bumjin/opt/anaconda3/lib/python3.9/site-packages/ray/rllib/agents/trainer.py", line 1925, in _make_workers
    return WorkerSet(
  File "/Users/bumjin/opt/anaconda3/lib/python3.9/site-packages/ray/rllib/evaluation/worker_set.py", line 123, in __init__
    self._local_worker = self._make_worker(
  File "/Users/bumjin/opt/anaconda3/lib/python3.9/site-packages/ray/rllib/evaluation/worker_set.py", line 497, in _make_worker
    worker = cls(
  File "/Users/bumjin/opt/anaconda3/lib/python3.9/site-packages/ray/rllib/evaluation/rollout_worker.py", line 588, in __init__
    self._build_policy_map(
  File "/Users/bumjin/opt/anaconda3/lib/python3.9/site-packages/ray/rllib/evaluation/rollout_worker.py", line 1547, in _build_policy_map
    preprocessor = ModelCatalog.get_preprocessor_for_space(
  File "/Users/bumjin/opt/anaconda3/lib/python3.9/site-packages/ray/rllib/models/catalog.py", line 687, in get_preprocessor_for_space
    raise Exception("Unknown config key `{}`, all keys: {}".format(
Exception: Unknown config key `q_hiddens`, all keys: ['_use_default_native_models', '_disable_preprocessor_api', 'fcnet_hiddens', 'fcnet_activation', 'conv_filters', 'conv_activation', 'post_fcnet_hiddens', 'post_fcnet_activation', 'free_log_std', 'no_final_linear', 'vf_share_layers', 'use_lstm', 'max_seq_len', 'lstm_cell_size', 'lstm_use_prev_action', 'lstm_use_prev_reward', '_time_major', 'use_attention', 'attention_num_transformer_units', 'attention_dim', 'attention_num_heads', 'attention_head_dim', 'attention_memory_inference', 'attention_memory_training', 'attention_position_wise_mlp_dim', 'attention_init_gru_gate_bias', 'attention_use_n_prev_actions', 'attention_use_n_prev_rewards', 'framestack', 'dim', 'grayscale', 'zero_mean', 'custom_model', 'custom_model_config', 'custom_action_dist', 'custom_preprocessor', 'lstm_use_prev_action_reward']

